<mujoco model="g1_29dof_revo2">
  <compiler angle="radian" meshdir="../meshes" />
  <option timestep="0.001" integrator="RK4" iterations="10" ls_iterations="10">
    <flag eulerdamp="enable"/>
  </option>

  <default>
    <default class="torso_motor">
      <joint damping="0.05" armature="0.01" frictionloss="0.2"/>
    </default>
    <default class="leg_motor">
      <joint damping="0.05" armature="0.01" frictionloss="0.2"/>
    </default>
    <default class="ankle_motor">
      <joint damping="0.05" armature="0.01" frictionloss="0.2"/>
    </default>
    <default class="arm_motor">
      <joint damping="0.05" armature="0.01" frictionloss="0.2"/>
    </default>
    <default class="wrist_motor">
      <joint damping="0.05" armature="0.01" frictionloss="0.1"/>
    </default>
    <default class="lefthand">
      <joint damping="0.5" armature="0.01" frictionloss="0.1"/>
      <default class="visual_hand">
        <geom group="1" type="mesh" contype="0" conaffinity="0" density="0"/>
      </default>
    </default>
    <default class="righthand">
      <joint damping="0.5" armature="0.01" frictionloss="0.1"/>
      <default class="visual_righthand">
        <geom group="1" type="mesh" contype="0" conaffinity="0" density="0"/>
      </default>
    </default>
    
  </default>

  <asset>
    <mesh name="pelvis" file="pelvis.STL" />
    <mesh name="pelvis_contour_link" file="pelvis_contour_link.STL" />
    <mesh name="left_hip_pitch_link" file="left_hip_pitch_link.STL" />
    <mesh name="left_hip_roll_link" file="left_hip_roll_link.STL" />
    <mesh name="left_hip_yaw_link" file="left_hip_yaw_link.STL" />
    <mesh name="left_knee_link" file="left_knee_link.STL" />
    <mesh name="left_ankle_pitch_link" file="left_ankle_pitch_link.STL" />
    <mesh name="left_ankle_roll_link" file="left_ankle_roll_link.STL" />
    <mesh name="right_hip_pitch_link" file="right_hip_pitch_link.STL" />
    <mesh name="right_hip_roll_link" file="right_hip_roll_link.STL" />
    <mesh name="right_hip_yaw_link" file="right_hip_yaw_link.STL" />
    <mesh name="right_knee_link" file="right_knee_link.STL" />
    <mesh name="right_ankle_pitch_link" file="right_ankle_pitch_link.STL" />
    <mesh name="right_ankle_roll_link" file="right_ankle_roll_link.STL" />
    <mesh name="waist_yaw_link" file="waist_yaw_link.STL" />
    <mesh name="waist_roll_link" file="waist_roll_link.STL" />
    <mesh name="torso_link" file="torso_link.STL" />
    <mesh name="logo_link" file="logo_link.STL" />
    <mesh name="head_link" file="head_link.STL" />
    <mesh name="waist_support_link" file="waist_support_link.STL" />
    <mesh name="left_shoulder_pitch_link" file="left_shoulder_pitch_link.STL" />
    <mesh name="left_shoulder_roll_link" file="left_shoulder_roll_link.STL" />
    <mesh name="left_shoulder_yaw_link" file="left_shoulder_yaw_link.STL" />
    <mesh name="left_elbow_link" file="left_elbow_link.STL" />
    <mesh name="left_wrist_roll_link" file="left_wrist_roll_link.STL" />
    <mesh name="left_wrist_pitch_link" file="left_wrist_pitch_link.STL" />
    <mesh name="left_wrist_yaw_link" file="left_wrist_yaw_link.STL" />
    <mesh name="tool_connector_cyl_x" file="tool_connector_cyl_x.STL" />
    <mesh name="right_shoulder_pitch_link" file="right_shoulder_pitch_link.STL" />
    <mesh name="right_shoulder_roll_link" file="right_shoulder_roll_link.STL" />
    <mesh name="right_shoulder_yaw_link" file="right_shoulder_yaw_link.STL" />
    <mesh name="right_elbow_link" file="right_elbow_link.STL" />
    <mesh name="right_wrist_roll_link" file="right_wrist_roll_link.STL" />
    <mesh name="right_wrist_pitch_link" file="right_wrist_pitch_link.STL" />
    <mesh name="right_wrist_yaw_link" file="right_wrist_yaw_link.STL" />

    <material name="silver" rgba="0.9 0.9 0.9 1"/>
    <material name="touch" rgba="0.53 0.81 0.92 1"/>

    <mesh name="left_base_link" file="../../revo2/meshes/revo2_left_hand/left_base_link.STL"/>
    <mesh name="left_base_visual_link" file="../../revo2/meshes/revo2_left_hand/left_base_visual_link.STL"/>
    <mesh name="left_thumb_metacarpal_link" file="../../revo2/meshes/revo2_left_hand/left_thumb_metacarpal_link.STL"/>
    <mesh name="left_thumb_proximal_link" file="../../revo2/meshes/revo2_left_hand/left_thumb_proximal_link.STL"/>
    <mesh name="left_thumb_proximal_visual_link" file="../../revo2/meshes/revo2_left_hand/left_thumb_proximal_visual_link.STL"/>
    <mesh name="left_thumb_distal_link" file="../../revo2/meshes/revo2_left_hand/left_thumb_distal_link.STL"/>
    <mesh name="left_thumb_touch_link" file="../../revo2/meshes/revo2_left_hand/left_thumb_touch_link.STL"/>
    <mesh name="left_index_proximal_link" file="../../revo2/meshes/revo2_left_hand/left_index_proximal_link.STL"/>
    <mesh name="left_index_distal_link" file="../../revo2/meshes/revo2_left_hand/left_index_distal_link.STL"/>
    <mesh name="left_index_touch_link" file="../../revo2/meshes/revo2_left_hand/left_index_touch_link.STL"/>
    <mesh name="left_middle_proximal_link" file="../../revo2/meshes/revo2_left_hand/left_middle_proximal_link.STL"/>
    <mesh name="left_middle_distal_link" file="../../revo2/meshes/revo2_left_hand/left_middle_distal_link.STL"/>
    <mesh name="left_middle_touch_link" file="../../revo2/meshes/revo2_left_hand/left_middle_touch_link.STL"/>
    <mesh name="left_ring_proximal_link" file="../../revo2/meshes/revo2_left_hand/left_ring_proximal_link.STL"/>
    <mesh name="left_ring_distal_link" file="../../revo2/meshes/revo2_left_hand/left_ring_distal_link.STL"/>
    <mesh name="left_ring_touch_link" file="../../revo2/meshes/revo2_left_hand/left_ring_touch_link.STL"/>
    <mesh name="left_pinky_proximal_link" file="../../revo2/meshes/revo2_left_hand/left_pinky_proximal_link.STL"/>
    <mesh name="left_pinky_distal_link" file="../../revo2/meshes/revo2_left_hand/left_pinky_distal_link.STL"/>
    <mesh name="left_pinky_touch_link" file="../../revo2/meshes/revo2_left_hand/left_pinky_touch_link.STL"/>

    <mesh name="right_base_link" file="../../revo2/meshes/revo2_right_hand/right_base_link.STL"/>
    <mesh name="right_base_link_collision" file="../../revo2/meshes/revo2_right_hand/right_base_link_collision.STL"/>
    <mesh name="right_thumb_metacarpal_link" file="../../revo2/meshes/revo2_right_hand/right_thumb_metacarpal_link.STL"/>
    <mesh name="right_thumb_proximal_link" file="../../revo2/meshes/revo2_right_hand/right_thumb_proximal_link.STL"/>
    <mesh name="right_thumb_proximal_link_collision" file="../../revo2/meshes/revo2_right_hand/right_thumb_proximal_link_collision.STL"/>
    <mesh name="right_thumb_distal_link" file="../../revo2/meshes/revo2_right_hand/right_thumb_distal_link.STL"/>
    <mesh name="right_thumb_tip" file="../../revo2/meshes/revo2_right_hand/right_thumb_tip.STL"/>
    <mesh name="right_thumb_touch_link" file="../../revo2/meshes/revo2_right_hand/right_thumb_touch_link.STL"/>
    <mesh name="right_index_proximal_link" file="../../revo2/meshes/revo2_right_hand/right_index_proximal_link.STL"/>
    <mesh name="right_index_distal_link" file="../../revo2/meshes/revo2_right_hand/right_index_distal_link.STL"/>
    <mesh name="right_index_tip" file="../../revo2/meshes/revo2_right_hand/right_index_tip.STL"/>
    <mesh name="right_index_touch_link" file="../../revo2/meshes/revo2_right_hand/right_index_touch_link.STL"/>
    <mesh name="right_middle_proximal_link" file="../../revo2/meshes/revo2_right_hand/right_middle_proximal_link.STL"/>
    <mesh name="right_middle_distal_link" file="../../revo2/meshes/revo2_right_hand/right_middle_distal_link.STL"/>
    <mesh name="right_middle_tip" file="../../revo2/meshes/revo2_right_hand/right_middle_tip.STL"/>
    <mesh name="right_middle_touch_link" file="../../revo2/meshes/revo2_right_hand/right_middle_touch_link.STL"/>
    <mesh name="right_ring_proximal_link" file="../../revo2/meshes/revo2_right_hand/right_ring_proximal_link.STL"/>
    <mesh name="right_ring_distal_link" file="../../revo2/meshes/revo2_right_hand/right_ring_distal_link.STL"/>
    <mesh name="right_ring_tip" file="../../revo2/meshes/revo2_right_hand/right_ring_tip.STL"/>
    <mesh name="right_ring_touch_link" file="../../revo2/meshes/revo2_right_hand/right_ring_touch_link.STL"/>
    <mesh name="right_pinky_proximal_link" file="../../revo2/meshes/revo2_right_hand/right_pinky_proximal_link.STL"/>
    <mesh name="right_pinky_distal_link" file="../../revo2/meshes/revo2_right_hand/right_pinky_distal_link.STL"/>
    <mesh name="right_pinky_tip" file="../../revo2/meshes/revo2_right_hand/right_pinky_tip.STL"/>
    <mesh name="right_pinky_touch_link" file="../../revo2/meshes/revo2_right_hand/right_pinky_touch_link.STL"/>
  </asset>

  <contact>
    <exclude body1="left_base_link" body2="left_thumb_metacarpal_link"/>
    <exclude body1="left_base_link" body2="left_thumb_proximal_link"/>
    <exclude body1="left_base_link" body2="left_index_proximal_link"/>
    <exclude body1="left_base_link" body2="left_middle_proximal_link"/>
    <exclude body1="left_base_link" body2="left_ring_proximal_link"/>
    <exclude body1="left_base_link" body2="left_pinky_proximal_link"/>
    <exclude body1="right_base_link" body2="right_thumb_metacarpal_link"/>
    <exclude body1="right_base_link" body2="right_thumb_proximal_link"/>
    <exclude body1="right_base_link" body2="right_index_proximal_link"/>
    <exclude body1="right_base_link" body2="right_middle_proximal_link"/>
    <exclude body1="right_base_link" body2="right_ring_proximal_link"/>
    <exclude body1="right_base_link" body2="right_pinky_proximal_link"/>
  </contact>

  <worldbody>
    <body name="pelvis" pos="0 0 0.793">
      <site name="imu" size="0.01" pos="0.0 0.0 0.0" />
      <inertial pos="0 0 -0.07605" quat="1 0 -0.000399148 0" mass="3.813"
        diaginertia="0.010549 0.0093089 0.0079184" />
      <joint name="floating_base_joint" type="free" limited="false" actuatorfrclimited="false" />
      <geom type="mesh" contype="0" conaffinity="0" group="1" density="0" rgba="0.2 0.2 0.2 1"
        mesh="pelvis" />
      <geom type="mesh" contype="0" conaffinity="0" group="1" density="0" rgba="0.7 0.7 0.7 1"
        mesh="pelvis_contour_link" />
      <geom type="mesh" rgba="0.7 0.7 0.7 1" mesh="pelvis_contour_link" />
      <body name="left_hip_pitch_link" pos="0 0.064452 -0.1027">
        <inertial pos="0.002741 0.047791 -0.02606" quat="0.954862 0.293964 0.0302556 0.030122"
          mass="1.35" diaginertia="0.00181517 0.00153422 0.00116212" />
        <joint name="left_hip_pitch_joint" pos="0 0 0" axis="0 1 0" range="-2.5307 2.8798"
          actuatorfrcrange="-88 88" class="leg_motor" />
        <geom type="mesh" contype="0" conaffinity="0" group="1" density="0" rgba="0.2 0.2 0.2 1"
          mesh="left_hip_pitch_link" />
        <geom type="mesh" rgba="0.2 0.2 0.2 1" mesh="left_hip_pitch_link" />
        <body name="left_hip_roll_link" pos="0 0.052 -0.030465" quat="0.996179 0 -0.0873386 0">
          <inertial pos="0.029812 -0.001045 -0.087934"
            quat="0.977808 -1.97119e-05 0.205576 -0.0403793" mass="1.52"
            diaginertia="0.00254986 0.00241169 0.00148755" />
          <joint name="left_hip_roll_joint" pos="0 0 0" axis="1 0 0" range="-0.5236 2.9671"
            actuatorfrcrange="-88 88" class="leg_motor" />
          <geom type="mesh" contype="0" conaffinity="0" group="1" density="0" rgba="0.7 0.7 0.7 1"
            mesh="left_hip_roll_link" />
          <geom type="mesh" rgba="0.7 0.7 0.7 1" mesh="left_hip_roll_link" />
          <body name="left_hip_yaw_link" pos="0.025001 0 -0.12412">
            <inertial pos="-0.057709 -0.010981 -0.15078" quat="0.600598 0.15832 0.223482 0.751181"
              mass="1.702" diaginertia="0.00776166 0.00717575 0.00160139" />
            <joint name="left_hip_yaw_joint" pos="0 0 0" axis="0 0 1" range="-2.7576 2.7576"
              actuatorfrcrange="-88 88" class="leg_motor" />
            <geom type="mesh" contype="0" conaffinity="0" group="1" density="0" rgba="0.7 0.7 0.7 1"
              mesh="left_hip_yaw_link" />
            <geom type="mesh" rgba="0.7 0.7 0.7 1" mesh="left_hip_yaw_link" />
            <body name="left_knee_link" pos="-0.078273 0.0021489 -0.17734"
              quat="0.996179 0 0.0873386 0">
              <inertial pos="0.005457 0.003964 -0.12074"
                quat="0.923418 -0.0327699 0.0158246 0.382067" mass="1.932"
                diaginertia="0.0113804 0.0112778 0.00146458" />
              <joint name="left_knee_joint" pos="0 0 0" axis="0 1 0" range="-0.087267 2.8798"
                actuatorfrcrange="-139 139" class="leg_motor" />
              <geom type="mesh" contype="0" conaffinity="0" group="1" density="0"
                rgba="0.7 0.7 0.7 1" mesh="left_knee_link" />
              <geom type="mesh" rgba="0.7 0.7 0.7 1" mesh="left_knee_link" />
              <body name="left_ankle_pitch_link" pos="0 -9.4445e-05 -0.30001">
                <inertial pos="-0.007269 0 0.011137" quat="0.603053 0.369225 0.369225 0.603053"
                  mass="0.074" diaginertia="1.89e-05 1.40805e-05 6.9195e-06" />
                <joint name="left_ankle_pitch_joint" pos="0 0 0" axis="0 1 0"
                  range="-0.87267 0.5236" actuatorfrcrange="-50 50"  class="ankle_motor"/>
                <geom type="mesh" contype="0" conaffinity="0" group="1" density="0"
                  rgba="0.7 0.7 0.7 1" mesh="left_ankle_pitch_link" />
                <geom type="mesh" rgba="0.7 0.7 0.7 1" mesh="left_ankle_pitch_link" />
                <body name="left_ankle_roll_link" pos="0 0 -0.017558">
                  <inertial pos="0.026505 0 -0.016425"
                    quat="-0.000481092 0.728482 -0.000618967 0.685065" mass="0.608"
                    diaginertia="0.00167218 0.0016161 0.000217621" />
                  <joint name="left_ankle_roll_joint" pos="0 0 0" axis="1 0 0"
                    range="-0.2618 0.2618" actuatorfrcrange="-50 50" class="ankle_motor"/>
                  <geom type="mesh" contype="0" conaffinity="0" group="1" density="0"
                    rgba="0.2 0.2 0.2 1" mesh="left_ankle_roll_link" />
                  <geom size="0.005" pos="-0.05 0.025 -0.03" rgba="0.2 0.2 0.2 1" />
                  <geom size="0.005" pos="-0.05 -0.025 -0.03" rgba="0.2 0.2 0.2 1" />
                  <geom size="0.005" pos="0.12 0.03 -0.03" rgba="0.2 0.2 0.2 1" />
                  <geom size="0.005" pos="0.12 -0.03 -0.03" rgba="0.2 0.2 0.2 1" />
                </body>
              </body>
            </body>
          </body>
        </body>
      </body>
      <body name="right_hip_pitch_link" pos="0 -0.064452 -0.1027">
        <inertial pos="0.002741 -0.047791 -0.02606" quat="0.954862 -0.293964 0.0302556 -0.030122"
          mass="1.35" diaginertia="0.00181517 0.00153422 0.00116212" />
        <joint name="right_hip_pitch_joint" pos="0 0 0" axis="0 1 0" range="-2.5307 2.8798"
          actuatorfrcrange="-88 88" class="leg_motor" />
        <geom type="mesh" contype="0" conaffinity="0" group="1" density="0" rgba="0.2 0.2 0.2 1"
          mesh="right_hip_pitch_link" />
        <geom type="mesh" rgba="0.2 0.2 0.2 1" mesh="right_hip_pitch_link" />
        <body name="right_hip_roll_link" pos="0 -0.052 -0.030465" quat="0.996179 0 -0.0873386 0">
          <inertial pos="0.029812 0.001045 -0.087934" quat="0.977808 1.97119e-05 0.205576 0.0403793"
            mass="1.52" diaginertia="0.00254986 0.00241169 0.00148755" />
          <joint name="right_hip_roll_joint" pos="0 0 0" axis="1 0 0" range="-2.9671 0.5236"
            actuatorfrcrange="-88 88" class="leg_motor" />
          <geom type="mesh" contype="0" conaffinity="0" group="1" density="0" rgba="0.7 0.7 0.7 1"
            mesh="right_hip_roll_link" />
          <geom type="mesh" rgba="0.7 0.7 0.7 1" mesh="right_hip_roll_link" />
          <body name="right_hip_yaw_link" pos="0.025001 0 -0.12412">
            <inertial pos="-0.057709 0.010981 -0.15078" quat="0.751181 0.223482 0.15832 0.600598"
              mass="1.702" diaginertia="0.00776166 0.00717575 0.00160139" />
            <joint name="right_hip_yaw_joint" pos="0 0 0" axis="0 0 1" range="-2.7576 2.7576"
              actuatorfrcrange="-88 88" class="leg_motor" />
            <geom type="mesh" contype="0" conaffinity="0" group="1" density="0" rgba="0.7 0.7 0.7 1"
              mesh="right_hip_yaw_link" />
            <geom type="mesh" rgba="0.7 0.7 0.7 1" mesh="right_hip_yaw_link" />
            <body name="right_knee_link" pos="-0.078273 -0.0021489 -0.17734"
              quat="0.996179 0 0.0873386 0">
              <inertial pos="0.005457 -0.003964 -0.12074"
                quat="0.923439 0.0345276 0.0116333 -0.382012" mass="1.932"
                diaginertia="0.011374 0.0112843 0.00146452" />
              <joint name="right_knee_joint" pos="0 0 0" axis="0 1 0" range="-0.087267 2.8798"
                actuatorfrcrange="-139 139" class="leg_motor" />
              <geom type="mesh" contype="0" conaffinity="0" group="1" density="0"
                rgba="0.7 0.7 0.7 1" mesh="right_knee_link" />
              <geom type="mesh" rgba="0.7 0.7 0.7 1" mesh="right_knee_link" />
              <body name="right_ankle_pitch_link" pos="0 9.4445e-05 -0.30001">
                <inertial pos="-0.007269 0 0.011137" quat="0.603053 0.369225 0.369225 0.603053"
                  mass="0.074" diaginertia="1.89e-05 1.40805e-05 6.9195e-06" />
                <joint name="right_ankle_pitch_joint" pos="0 0 0" axis="0 1 0"
                  range="-0.87267 0.5236" actuatorfrcrange="-50 50" class="ankle_motor" />
                <geom type="mesh" contype="0" conaffinity="0" group="1" density="0"
                  rgba="0.7 0.7 0.7 1" mesh="right_ankle_pitch_link" />
                <geom type="mesh" rgba="0.7 0.7 0.7 1" mesh="right_ankle_pitch_link" />
                <body name="right_ankle_roll_link" pos="0 0 -0.017558">
                  <inertial pos="0.026505 0 -0.016425"
                    quat="0.000481092 0.728482 0.000618967 0.685065" mass="0.608"
                    diaginertia="0.00167218 0.0016161 0.000217621" />
                  <joint name="right_ankle_roll_joint" pos="0 0 0" axis="1 0 0"
                    range="-0.2618 0.2618" actuatorfrcrange="-50 50" class="ankle_motor" />
                  <geom type="mesh" contype="0" conaffinity="0" group="1" density="0"
                    rgba="0.2 0.2 0.2 1" mesh="right_ankle_roll_link" />
                  <geom size="0.005" pos="-0.05 0.025 -0.03" rgba="0.2 0.2 0.2 1" />
                  <geom size="0.005" pos="-0.05 -0.025 -0.03" rgba="0.2 0.2 0.2 1" />
                  <geom size="0.005" pos="0.12 0.03 -0.03" rgba="0.2 0.2 0.2 1" />
                  <geom size="0.005" pos="0.12 -0.03 -0.03" rgba="0.2 0.2 0.2 1" />
                </body>
              </body>
            </body>
          </body>
        </body>
      </body>
      <body name="waist_yaw_link">
        <inertial pos="0.003964 0 0.018769" quat="-0.0178291 0.628464 0.0282471 0.777121"
          mass="0.244" diaginertia="0.000158561 0.000124229 9.67669e-05" />
        <joint name="waist_yaw_joint" pos="0 0 0" axis="0 0 1" range="-2.618 2.618"
          actuatorfrcrange="-88 88" class="torso_motor"/>
        <geom type="mesh" contype="0" conaffinity="0" group="1" density="0" rgba="0.7 0.7 0.7 1"
          mesh="waist_yaw_link" />
        <body name="waist_roll_link" pos="-0.0039635 0 0.035">
          <inertial pos="0 -0.000236 0.010111" quat="0.99979 0.020492 0 0" mass="0.047"
            diaginertia="7.515e-06 6.40206e-06 3.98394e-06" />
          <joint name="waist_roll_joint" pos="0 0 0" axis="1 0 0" range="-0.52 0.52"
            actuatorfrcrange="-50 50" class="torso_motor"/>
          <geom type="mesh" contype="0" conaffinity="0" group="1" density="0" rgba="0.7 0.7 0.7 1"
            mesh="waist_roll_link" />
          <site name="secondary_imu" size="0.01" pos="-0.03959 -0.00224 0.13792"/>
          <body name="torso_link" pos="0 0 0.019">
            <inertial pos="0.00331658 0.000261533 0.179856"
              quat="0.999831 0.000376204 0.0179895 -0.00377704" mass="9.598"
              diaginertia="0.12407 0.111951 0.0325382" />
            <joint name="waist_pitch_joint" pos="0 0 0" axis="0 1 0" range="-0.52 0.52"
              actuatorfrcrange="-50 50" class="torso_motor"/>
            <geom type="mesh" contype="0" conaffinity="0" group="1" density="0" rgba="0.7 0.7 0.7 1"
              mesh="torso_link" />
            <geom type="mesh" rgba="0.7 0.7 0.7 1" mesh="torso_link" />
            <geom pos="0.0039635 0 -0.054" quat="1 0 0 0" type="mesh" contype="0" conaffinity="0"
              group="1" density="0" rgba="0.2 0.2 0.2 1" mesh="logo_link" />
            <geom pos="0.0039635 0 -0.054" quat="1 0 0 0" type="mesh" rgba="0.2 0.2 0.2 1"
              mesh="logo_link" />
            <geom pos="0.0039635 0 -0.054" type="mesh" contype="0" conaffinity="0" group="1"
              density="0" rgba="0.2 0.2 0.2 1" mesh="head_link" />
            <geom pos="0.0039635 0 -0.054" type="mesh" rgba="0.2 0.2 0.2 1" mesh="head_link" />
            <geom pos="0.0039635 0 -0.054" quat="1 0 0 0" type="mesh" contype="0" conaffinity="0"
              group="1" density="0" rgba="0.7 0.7 0.7 1" mesh="waist_support_link" />
            <geom pos="0.0039635 0 -0.054" quat="1 0 0 0" type="mesh" rgba="0.7 0.7 0.7 1"
              mesh="waist_support_link" />
            <body name="left_shoulder_pitch_link" pos="0.0039563 0.10022 0.23778"
              quat="0.990264 0.139201 1.38722e-05 -9.86868e-05">
              <inertial pos="0 0.035892 -0.011628" quat="0.654152 0.0130458 -0.326267 0.68225"
                mass="0.718" diaginertia="0.000465864 0.000432842 0.000406394" />
              <joint name="left_shoulder_pitch_joint" pos="0 0 0" axis="0 1 0"
                range="-3.0892 2.6704" actuatorfrcrange="-25 25" class="arm_motor" />
              <geom type="mesh" contype="0" conaffinity="0" group="1" density="0"
                rgba="0.7 0.7 0.7 1" mesh="left_shoulder_pitch_link" />
              <geom size="0.03 0.025" pos="0 0.04 -0.01" quat="0.707107 0 0.707107 0"
                type="cylinder" rgba="0.7 0.7 0.7 1" />
              <body name="left_shoulder_roll_link" pos="0 0.038 -0.013831"
                quat="0.990268 -0.139172 0 0">
                <inertial pos="-0.000227 0.00727 -0.063243"
                  quat="0.701256 -0.0196223 -0.00710317 0.712604" mass="0.643"
                  diaginertia="0.000691311 0.000618011 0.000388977" />
                <joint name="left_shoulder_roll_joint" pos="0 0 0" axis="1 0 0"
                  range="-1.5882 2.2515" actuatorfrcrange="-25 25" class="arm_motor" />
                <geom type="mesh" contype="0" conaffinity="0" group="1" density="0"
                  rgba="0.7 0.7 0.7 1" mesh="left_shoulder_roll_link" />
                <geom size="0.03 0.015" pos="-0.004 0.006 -0.053" type="cylinder"
                  rgba="0.7 0.7 0.7 1" />
                <body name="left_shoulder_yaw_link" pos="0 0.00624 -0.1032">
                  <inertial pos="0.010773 -0.002949 -0.072009"
                    quat="0.716879 -0.0964829 -0.0679942 0.687134" mass="0.734"
                    diaginertia="0.00106187 0.00103217 0.000400661" />
                  <joint name="left_shoulder_yaw_joint" pos="0 0 0" axis="0 0 1"
                    range="-2.618 2.618" actuatorfrcrange="-25 25" class="arm_motor" />
                  <geom type="mesh" contype="0" conaffinity="0" group="1" density="0"
                    rgba="0.7 0.7 0.7 1" mesh="left_shoulder_yaw_link" />
                  <geom type="mesh" rgba="0.7 0.7 0.7 1" mesh="left_shoulder_yaw_link" />
                  <body name="left_elbow_link" pos="0.015783 0 -0.080518">
                    <inertial pos="0.064956 0.004454 -0.010062"
                      quat="0.541765 0.636132 0.388821 0.388129" mass="0.6"
                      diaginertia="0.000443035 0.000421612 0.000259353" />
                    <joint name="left_elbow_joint" pos="0 0 0" axis="0 1 0" range="-1.0472 2.0944"
                      actuatorfrcrange="-25 25" class="arm_motor" />
                    <geom type="mesh" contype="0" conaffinity="0" group="1" density="0"
                      rgba="0.7 0.7 0.7 1" mesh="left_elbow_link" />
                    <geom type="mesh" rgba="0.7 0.7 0.7 1" mesh="left_elbow_link" />
                    <body name="left_wrist_roll_link" pos="0.1 0.00188791 -0.01">
                      <inertial pos="0.0171394 0.000537591 4.8864e-07"
                        quat="0.575338 0.411667 -0.574906 0.411094" mass="0.085445"
                        diaginertia="5.48211e-05 4.96646e-05 3.57798e-05" />
                      <joint name="left_wrist_roll_joint" pos="0 0 0" axis="1 0 0"
                        range="-1.97222 1.97222" actuatorfrcrange="-25 25" class="arm_motor" />
                      <geom type="mesh" contype="0" conaffinity="0" group="1" density="0"
                        rgba="0.7 0.7 0.7 1" mesh="left_wrist_roll_link" />
                      <geom type="mesh" rgba="0.7 0.7 0.7 1" mesh="left_wrist_roll_link" />
                      <body name="left_wrist_pitch_link" pos="0.038 0 0">
                        <inertial pos="0.0229999 -0.00111685 -0.00111658"
                          quat="0.249998 0.661363 0.293036 0.643608" mass="0.48405"
                          diaginertia="0.000430353 0.000429873 0.000164648" />
                        <joint name="left_wrist_pitch_joint" pos="0 0 0" axis="0 1 0"
                          range="-1.61443 1.61443" actuatorfrcrange="-5 5" class="wrist_motor" />
                        <geom type="mesh" contype="0" conaffinity="0" group="1" density="0"
                          rgba="0.7 0.7 0.7 1" mesh="left_wrist_pitch_link" />
                        <geom type="mesh" rgba="0.7 0.7 0.7 1" mesh="left_wrist_pitch_link" />
                        <body name="left_wrist_yaw_link" pos="0.046 0 0">
                          <inertial pos="0.02200381568 0.00049485096 0.00053861123" mass="0.08457647"
                            fullinertia="0.00004929128828 0.00005973338134 0.00003928083826 -0.00000045735494 0.00000445867591 0.00000043217198" />
                          <joint name="left_wrist_yaw_joint" pos="0 0 0" axis="0 0 1"
                            range="-1.61443 1.61443" actuatorfrcrange="-5 5" class="wrist_motor" />
                          <geom type="mesh" contype="0" conaffinity="0" group="1" density="0"
                            rgba="0.7 0.7 0.7 1" mesh="left_wrist_yaw_link" />
                          <geom type="mesh" rgba="0.7 0.7 0.7 1" mesh="left_wrist_yaw_link" />
                          <body name="left_tool_connector_link" pos="0.0415 0.003 0">
                            <inertial pos="0.011 0 0" quat="1 0 0 0" mass="0.01"
                              diaginertia="1e-06 1e-06 1e-06" />
                            <geom type="mesh" contype="0" conaffinity="0" group="1" density="0"
                              rgba="0.7 0.7 0.7 1" mesh="tool_connector_cyl_x" />
                            <geom type="mesh" rgba="0.7 0.7 0.7 1" mesh="tool_connector_cyl_x" />
                            <body name="left_tool_attach" pos="0.022 0 0"
                              euler="-1.5707963267948966 1.5707963267948966 0">
                              <body name="left_base_link" pos="0 0 0" quat="1 0 0 0" childclass="lefthand">
                                <geom type="mesh" contype="0" conaffinity="0" group="1" density="0" rgba="1 1 1 1" mesh="left_base_link"/>
                                <geom type="mesh" contype="0" conaffinity="0" group="1" density="0" rgba="1 1 1 1" mesh="left_base_visual_link"/>
                                <geom type="mesh" rgba="1 1 1 1" mesh="left_base_link"/>
                                <body name="left_thumb_metacarpal_link" pos="0.0045 -0.019 0.027825" quat="0.99648 0 0 0.0838365">
                                  <inertial pos="1.52304e-05 -0.0070724 -0.0042084" quat="0.882814 0.0586739 -0.0302438 0.465061" mass="0.01" diaginertia="1.66114e-07 1.56005e-07 4.93864e-08"/>
                                  <joint name="left_thumb_metacarpal_joint" pos="0 0 0" axis="0 0 1" range="0 1.57" actuatorfrcrange="-0.5 0.5"/>
                                  <geom type="mesh" contype="0" conaffinity="0" group="1" density="0" rgba="1 1 1 1" mesh="left_thumb_metacarpal_link"/>
                                  <geom type="mesh" rgba="1 1 1 1" mesh="left_thumb_metacarpal_link"/>
                                  <body name="left_thumb_proximal_link" pos="0 -0.014227 0" quat="0.986557 -0.0765206 0.124804 -0.0726253">
                                    <inertial pos="-3.69149e-07 -0.0277016 -0.00202668" quat="0.503512 0.49651 -0.496419 0.50351" mass="0.05" diaginertia="2.56296e-06 2.40451e-06 5.11892e-07"/>
                                    <joint name="left_thumb_proximal_joint" pos="0 0 0" axis="-1 0 0" range="0 1.03" actuatorfrcrange="-1.1 1.1"/>
                                    <geom type="mesh" contype="0" conaffinity="0" group="1" density="0" rgba="1 1 1 1" mesh="left_thumb_proximal_link"/>
                                    <geom type="mesh" contype="0" conaffinity="0" group="1" density="0" rgba="1 1 1 1" mesh="left_thumb_proximal_visual_link"/>
                                    <geom type="mesh" rgba="1 1 1 1" mesh="left_thumb_proximal_link"/>
                                    <body name="left_thumb_distal_link" pos="0 -0.052 0">
                                      <inertial pos="1.60632e-07 -0.011755 1.13715e-05" quat="0.469581 0.528672 -0.528503 0.46977" mass="0.012" diaginertia="4.42098e-07 3.35619e-07 2.27749e-07"/>
                                      <joint name="left_thumb_distal_joint" pos="0 0 0" axis="-1 0 0" range="0 1.03" actuatorfrcrange="-1.1 1.1"/>
                                      <geom type="mesh" contype="0" conaffinity="0" group="1" density="0" rgba="1 1 1 1" mesh="left_thumb_distal_link"/>
                                      <geom type="mesh" rgba="1 1 1 1" mesh="left_thumb_distal_link"/>
                                      <geom pos="0 -0.013836 0.0076686" quat="0.99618 0.0873286 0 0" type="mesh" contype="0" conaffinity="0" group="1" density="0" material="touch" mesh="left_thumb_touch_link"/>
                                      <geom pos="0 -0.013836 0.0076686" quat="0.99618 0.0873286 0 0" type="mesh" material="touch" mesh="left_thumb_touch_link"/>
                                    </body>
                                  </body>
                                </body>
                                <body name="left_index_proximal_link" pos="-0.0021349 -0.029578 0.080876" quat="0.992147 0.0522807 0.0783652 0.0822789">
                                  <inertial pos="-0.00223539 -3.80545e-06 0.0176439" quat="0.999799 -0.000616966 0.0200059 -0.000754874" mass="0.009" diaginertia="2.52119e-07 2.36343e-07 9.27846e-08"/>
                                  <joint name="left_index_proximal_joint" pos="0 0 0" axis="0 1 0" range="0 1.41" actuatorfrcrange="-2 2"/>
                                  <geom type="mesh" contype="0" conaffinity="0" group="1" density="0" rgba="1 1 1 1" mesh="left_index_proximal_link"/>
                                  <geom type="mesh" rgba="1 1 1 1" mesh="left_index_proximal_link"/>
                                  <body name="left_index_distal_link" pos="0 0 0.032">
                                    <inertial pos="0.00506249 5.29762e-08 0.0165189" quat="0.684726 0.176497 0.176494 0.684725" mass="0.011" diaginertia="7.85565e-07 7.71543e-07 8.7333e-08"/>
                                    <joint name="left_index_distal_joint" pos="0 0 0" axis="0 1 0" range="0 1.63" actuatorfrcrange="-2 2"/>
                                    <geom type="mesh" contype="0" conaffinity="0" group="1" density="0" rgba="1 1 1 1" mesh="left_index_distal_link"/>
                                    <geom type="mesh" rgba="1 1 1 1" mesh="left_index_distal_link"/>
                                    <geom pos="0.014497 0 0.023303" quat="0.971859 0 0.235565 0" type="mesh" contype="0" conaffinity="0" group="1" density="0" material="touch" mesh="left_index_touch_link"/>
                                    <geom pos="0.014497 0 0.023303" quat="0.971859 0 0.235565 0" type="mesh" material="touch" mesh="left_index_touch_link"/>
                                  </body>
                                </body>
                                <body name="left_middle_proximal_link" pos="-0.0045935 -0.010061 0.084993" quat="0.996681 0.0175235 0.0746069 0.0274369">
                                  <inertial pos="-0.00222419 -3.61991e-06 0.020305" quat="0.999816 -0.000555887 0.019164 -0.000888931" mass="0.009" diaginertia="3.6726e-07 3.52522e-07 1.11867e-07"/>
                                  <joint name="left_middle_proximal_joint" pos="0 0 0" axis="0 1 0" range="0 1.41" actuatorfrcrange="-2 2"/>
                                  <geom type="mesh" contype="0" conaffinity="0" group="1" density="0" rgba="1 1 1 1" mesh="left_middle_proximal_link"/>
                                  <geom type="mesh" rgba="1 1 1 1" mesh="left_middle_proximal_link"/>
                                  <body name="left_middle_distal_link" pos="0 0 0.037" quat="0.997999 0 0.0632278 0">
                                    <inertial pos="0.00346095 -2.38806e-08 0.0196735" quat="0.696456 0.122525 0.12254 0.696362" mass="0.011" diaginertia="1.06829e-06 1.04939e-06 1.1141e-07"/>
                                    <joint name="left_middle_distal_joint" pos="0 0 0" axis="0 1 0" range="0 1.63" actuatorfrcrange="-2 2"/>
                                    <geom type="mesh" contype="0" conaffinity="0" group="1" density="0" rgba="1 1 1 1" mesh="left_middle_distal_link"/>
                                    <geom type="mesh" rgba="1 1 1 1" mesh="left_middle_distal_link"/>
                                    <geom pos="0.012493 0 0.028393" quat="0.984807 0 0.17365 0" type="mesh" contype="0" conaffinity="0" group="1" density="0" material="touch" mesh="left_middle_touch_link"/>
                                    <geom pos="0.012493 0 0.028393" quat="0.984807 0 0.17365 0" type="mesh" material="touch" mesh="left_middle_touch_link"/>
                                  </body>
                                </body>
                                <body name="left_ring_proximal_link" pos="-0.0046877 0.010026 0.083982" quat="0.996722 -0.0175386 0.0740633 -0.0274276">
                                  <inertial pos="-0.00234461 -5.32058e-06 0.0191786" quat="0.999832 -0.00064229 0.0183097 -0.000744974" mass="0.009" diaginertia="3.14467e-07 2.97624e-07 1.01836e-07"/>
                                  <joint name="left_ring_proximal_joint" pos="0 0 0" axis="0 1 0" range="0 1.41" actuatorfrcrange="-2 2"/>
                                  <geom type="mesh" contype="0" conaffinity="0" group="1" density="0" rgba="1 1 1 1" mesh="left_ring_proximal_link"/>
                                  <geom type="mesh" rgba="1 1 1 1" mesh="left_ring_proximal_link"/>
                                  <body name="left_ring_distal_link" pos="0 0 0.035" quat="0.997999 0 0.0632278 0">
                                    <inertial pos="0.00330806 4.53539e-08 0.0191705" quat="0.696112 0.124209 0.124209 0.696112" mass="0.011" diaginertia="1.01271e-06 9.96667e-07 1.02713e-07"/>
                                    <joint name="left_ring_distal_joint" pos="0 0 0" axis="0 1 0" range="0 1.63" actuatorfrcrange="-2 2"/>
                                    <geom type="mesh" contype="0" conaffinity="0" group="1" density="0" rgba="1 1 1 1" mesh="left_ring_distal_link"/>
                                    <geom type="mesh" rgba="1 1 1 1" mesh="left_ring_distal_link"/>
                                    <geom pos="0.012028 0 0.027796" quat="0.984807 0 0.17365 0" type="mesh" contype="0" conaffinity="0" group="1" density="0" material="touch" mesh="left_ring_touch_link"/>
                                    <geom pos="0.012028 0 0.027796" quat="0.984807 0 0.17365 0" type="mesh" material="touch" mesh="left_ring_touch_link"/>
                                  </body>
                                </body>
                                <body name="left_pinky_proximal_link" pos="-0.0023733 0.029356 0.078694" quat="0.992245 -0.052387 0.0771065 -0.0822136">
                                  <inertial pos="-0.00213267 -7.0226e-06 0.016068" quat="0.999803 -0.000517111 0.0198307 -0.000287779" mass="0.009" diaginertia="1.97736e-07 1.82023e-07 8.19937e-08"/>
                                  <joint name="left_pinky_proximal_joint" pos="0 0 0" axis="0 1 0" range="0 1.41" actuatorfrcrange="-2 2"/>
                                  <geom type="mesh" contype="0" conaffinity="0" group="1" density="0" rgba="1 1 1 1" mesh="left_pinky_proximal_link"/>
                                  <geom type="mesh" rgba="1 1 1 1" mesh="left_pinky_proximal_link"/>
                                  <body name="left_pinky_distal_link" pos="0 0 0.029">
                                    <inertial pos="0.00473719 -1.39005e-07 0.0150047" quat="0.682047 0.186482 0.186461 0.682106" mass="0.011" diaginertia="6.20812e-07 6.0761e-07 8.19131e-08"/>
                                    <joint name="left_pinky_distal_joint" pos="0 0 0" axis="0 1 0" range="0 1.63" actuatorfrcrange="-2 2"/>
                                    <geom type="mesh" contype="0" conaffinity="0" group="1" density="0" rgba="1 1 1 1" mesh="left_pinky_distal_link"/>
                                    <geom type="mesh" rgba="1 1 1 1" mesh="left_pinky_distal_link"/>
                                    <geom pos="0.01401 0 0.021124" quat="0.971859 0 0.235565 0" type="mesh" contype="0" conaffinity="0" group="1" density="0" material="touch" mesh="left_pinky_touch_link"/>
                                    <geom pos="0.01401 0 0.021124" quat="0.971859 0 0.235565 0" type="mesh" material="touch" mesh="left_pinky_touch_link"/>
                                  </body>
                                </body>
                              </body>
                            </body>
                          </body>
                        </body>
                      </body>
                    </body>
                  </body>
                </body>
              </body>
            </body>
            <body name="right_shoulder_pitch_link" pos="0.0039563 -0.10021 0.23778"
              quat="0.990264 -0.139201 1.38722e-05 9.86868e-05">
              <inertial pos="0 -0.035892 -0.011628" quat="0.68225 -0.326267 0.0130458 0.654152"
                mass="0.718" diaginertia="0.000465864 0.000432842 0.000406394" />
              <joint name="right_shoulder_pitch_joint" pos="0 0 0" axis="0 1 0"
                range="-3.0892 2.6704" actuatorfrcrange="-25 25" class="arm_motor" />
              <geom type="mesh" contype="0" conaffinity="0" group="1" density="0"
                rgba="0.7 0.7 0.7 1" mesh="right_shoulder_pitch_link" />
              <geom size="0.03 0.025" pos="0 -0.04 -0.01" quat="0.707107 0 0.707107 0"
                type="cylinder" rgba="0.7 0.7 0.7 1" />
              <body name="right_shoulder_roll_link" pos="0 -0.038 -0.013831"
                quat="0.990268 0.139172 0 0">
                <inertial pos="-0.000227 -0.00727 -0.063243"
                  quat="0.712604 -0.00710317 -0.0196223 0.701256" mass="0.643"
                  diaginertia="0.000691311 0.000618011 0.000388977" />
                <joint name="right_shoulder_roll_joint" pos="0 0 0" axis="1 0 0"
                  range="-2.2515 1.5882" actuatorfrcrange="-25 25" class="arm_motor" />
                <geom type="mesh" contype="0" conaffinity="0" group="1" density="0"
                  rgba="0.7 0.7 0.7 1" mesh="right_shoulder_roll_link" />
                <geom size="0.03 0.015" pos="-0.004 -0.006 -0.053" type="cylinder"
                  rgba="0.7 0.7 0.7 1" />
                <body name="right_shoulder_yaw_link" pos="0 -0.00624 -0.1032">
                  <inertial pos="0.010773 0.002949 -0.072009"
                    quat="0.687134 -0.0679942 -0.0964829 0.716879" mass="0.734"
                    diaginertia="0.00106187 0.00103217 0.000400661" />
                  <joint name="right_shoulder_yaw_joint" pos="0 0 0" axis="0 0 1"
                    range="-2.618 2.618" actuatorfrcrange="-25 25" class="arm_motor" />
                  <geom type="mesh" contype="0" conaffinity="0" group="1" density="0"
                    rgba="0.7 0.7 0.7 1" mesh="right_shoulder_yaw_link" />
                  <geom type="mesh" rgba="0.7 0.7 0.7 1" mesh="right_shoulder_yaw_link" />
                  <body name="right_elbow_link" pos="0.015783 0 -0.080518">
                    <inertial pos="0.064956 -0.004454 -0.010062"
                      quat="0.388129 0.388821 0.636132 0.541765" mass="0.6"
                      diaginertia="0.000443035 0.000421612 0.000259353" />
                    <joint name="right_elbow_joint" pos="0 0 0" axis="0 1 0" range="-1.0472 2.0944"
                      actuatorfrcrange="-25 25" class="arm_motor" />
                    <geom type="mesh" contype="0" conaffinity="0" group="1" density="0"
                      rgba="0.7 0.7 0.7 1" mesh="right_elbow_link" />
                    <geom type="mesh" rgba="0.7 0.7 0.7 1" mesh="right_elbow_link" />
                    <body name="right_wrist_roll_link" pos="0.1 -0.00188791 -0.01">
                      <inertial pos="0.0171394 -0.000537591 4.8864e-07"
                        quat="0.411667 0.575338 -0.411094 0.574906" mass="0.085445"
                        diaginertia="5.48211e-05 4.96646e-05 3.57798e-05" />
                      <joint name="right_wrist_roll_joint" pos="0 0 0" axis="1 0 0"
                        range="-1.97222 1.97222" actuatorfrcrange="-25 25" class="arm_motor" />
                      <geom type="mesh" contype="0" conaffinity="0" group="1" density="0"
                        rgba="0.7 0.7 0.7 1" mesh="right_wrist_roll_link" />
                      <geom type="mesh" rgba="0.7 0.7 0.7 1" mesh="right_wrist_roll_link" />
                      <body name="right_wrist_pitch_link" pos="0.038 0 0">
                        <inertial pos="0.0229999 0.00111685 -0.00111658"
                          quat="0.643608 0.293036 0.661363 0.249998" mass="0.48405"
                          diaginertia="0.000430353 0.000429873 0.000164648" />
                        <joint name="right_wrist_pitch_joint" pos="0 0 0" axis="0 1 0"
                          range="-1.61443 1.61443" actuatorfrcrange="-5 5" class="wrist_motor" />
                        <geom type="mesh" contype="0" conaffinity="0" group="1" density="0"
                          rgba="0.7 0.7 0.7 1" mesh="right_wrist_pitch_link" />
                        <geom type="mesh" rgba="0.7 0.7 0.7 1" mesh="right_wrist_pitch_link" />
                        <body name="right_wrist_yaw_link" pos="0.046 0 0">
                          <inertial pos="0.02200381568 -0.00049485096 0.00053861123" mass="0.08457647"
                            fullinertia="0.00004929128828 0.00005973338134 0.00003928083826 0.00000045735494 0.00000445867591 -0.00000043217198" />
                          <joint name="right_wrist_yaw_joint" pos="0 0 0" axis="0 0 1"
                            range="-1.61443 1.61443" actuatorfrcrange="-5 5" class="wrist_motor" />
                          <geom type="mesh" contype="0" conaffinity="0" group="1" density="0"
                            rgba="0.7 0.7 0.7 1" mesh="right_wrist_yaw_link" />
                          <geom type="mesh" rgba="0.7 0.7 0.7 1" mesh="right_wrist_yaw_link" />
                          <body name="right_tool_connector_link" pos="0.0415 -0.003 0">
                            <inertial pos="0.011 0 0" quat="1 0 0 0" mass="0.01"
                              diaginertia="1e-06 1e-06 1e-06" />
                            <geom type="mesh" contype="0" conaffinity="0" group="1" density="0"
                              rgba="0.7 0.7 0.7 1" mesh="tool_connector_cyl_x" />
                            <geom type="mesh" rgba="0.7 0.7 0.7 1" mesh="tool_connector_cyl_x" />
                            <body name="right_tool_attach" pos="0.022 0 0"
                              euler="1.5707963267948966 1.5707963267948966 0">
                              <body name="right_base_link" pos="0 0 0" quat="1 0 0 0" childclass="righthand">
                                <geom name="right_base_link_visual" type="mesh" class="visual_righthand" material="silver" mesh="right_base_link"/>
                                <geom name="right_base_link_collision" type="mesh" mesh="right_base_link_collision"/>
                                <site name="right_grasp_site" pos="0.11 0.0 0.03" group="4"/>
                                <body name="right_thumb_metacarpal_link" pos="0.005619 0.019867 0.027825" quat="-3.0799e-07 0.0838478 0.996479 -3.66027e-06">
                                  <inertial pos="-1.51106e-05 0.00707243 0.00420847" mass="0.01" diaginertia="0.0001 0.0001 0.0001"/>
                                  <joint name="right_thumb_metacarpal_joint" pos="0 0 0" axis="0 0 1" range="0 1.5184" actuatorfrcrange="-0.5 0.5"/>
                                  <geom name="right_thumb_metacarpal_link_visual" type="mesh" class="visual_righthand" material="silver" mesh="right_thumb_metacarpal_link"/>
                                  <geom name="right_thumb_metacarpal_link_collision" type="mesh" mesh="right_thumb_metacarpal_link"/>
                                  <body name="right_thumb_proximal_link" pos="0 0.014227 0" quat="0.124805 -0.0726357 -0.986555 0.0765254">
                                    <inertial pos="-4.57221e-07 0.025009 -0.00175049" mass="0.05" diaginertia="0.0001 0.0001 0.0001"/>
                                    <joint name="right_thumb_proximal_joint" pos="0 0 0" axis="1 0 0" range="0 1.0472" actuatorfrcrange="-1.1 1.1"/>
                                    <geom name="right_thumb_proximal_link_visual" type="mesh" class="visual_righthand" material="silver" mesh="right_thumb_proximal_link"/>
                                    <geom name="right_thumb_proximal_link_collision" type="mesh" mesh="right_thumb_proximal_link_collision"/>
                                    <body name="right_thumb_distal_link" pos="0 0.052 0">
                                      <inertial pos="-5.88258e-09 0.0117545 1.13324e-05" mass="0.01" diaginertia="0.0001 0.0001 0.0001"/>
                                      <joint name="right_thumb_distal_joint" pos="0 0 0" axis="1 0 0" range="0 1.0472" actuatorfrcrange="-1.1 1.1"/>
                                      <geom name="right_thumb_distal_link_visual" type="mesh" class="visual_righthand" material="silver" mesh="right_thumb_distal_link"/>
                                      <geom name="right_thumb_distal_link_collision" type="mesh" mesh="right_thumb_distal_link"/>
                                      <body name="right_thumb_tip" pos="0 0.026529 -0.0017734" quat="0.999443 -0.0333688 0 0">
                                        <inertial pos="0 -8.79922e-05 0" mass="0.001" diaginertia="0.0001 0.0001 0.0001"/>
                                        <geom name="right_thumb_tip_visual" type="mesh" class="visual_righthand" material="silver" mesh="right_thumb_tip"/>
                                        <geom name="right_thumb_tip_collision" type="mesh" mesh="right_thumb_tip"/>
                                        <geom name="right_thumb_touch_visual" type="mesh" class="visual_righthand" material="touch" mesh="right_thumb_touch_link"/>
                                        <geom name="right_thumb_touch_collision" type="mesh" material="touch" mesh="right_thumb_touch_link"/>
                                        <site name="right_thumb_tip" pos="0 -0.05 0.015" group="4"/>
                                      </body>
                                    </body>
                                  </body>
                                </body>
                                <body name="right_index_proximal_link" pos="-0.0021181 0.029568 0.080876" quat="0.992147 -0.0522807 0.0783652 -0.0822789">
                                  <inertial pos="-0.00223495 3.15875e-06 0.0176402" mass="0.009" diaginertia="0.0001 0.0001 0.0001"/>
                                  <joint name="right_index_proximal_joint" pos="0 0 0" axis="0 1 0" range="0 1.4661" actuatorfrcrange="-2 2"/>
                                  <geom name="right_index_proximal_link_visual" type="mesh" class="visual_righthand" material="silver" mesh="right_index_proximal_link"/>
                                  <geom name="right_index_proximal_link_collision" type="mesh" mesh="right_index_proximal_link"/>
                                  <body name="right_index_distal_link" pos="0 0 0.032">
                                    <inertial pos="0.00418341 1.1643e-07 0.0153643" mass="0.009" diaginertia="0.0001 0.0001 0.0001"/>
                                    <joint name="right_index_distal_joint" pos="0 0 0" axis="0 1 0" range="0 1.693" actuatorfrcrange="-2 2"/>
                                    <geom name="right_index_distal_link_visual" type="mesh" class="visual_righthand" material="silver" mesh="right_index_distal_link"/>
                                    <geom name="right_index_distal_link_collision" type="mesh" mesh="right_index_distal_link"/>
                                    <body name="right_index_tip" pos="0.011097 0 0.035739" quat="0.971859 0 0.235565 0">
                                      <inertial pos="0 0 0" mass="0.001" diaginertia="0.0001 0.0001 0.0001"/>
                                      <geom name="right_index_tip_visual" type="mesh" class="visual_righthand" material="silver" mesh="right_index_tip"/>
                                      <geom name="right_index_tip_collision" type="mesh" mesh="right_index_tip"/>
                                      <geom name="right_index_touch_visual" type="mesh" class="visual_righthand" material="touch" mesh="right_index_touch_link"/>
                                      <geom name="right_index_touch_collision" type="mesh" material="touch" mesh="right_index_touch_link"/>
                                      <site name="right_index_tip" pos="0 -0.05 0.015" group="4"/>
                                    </body>
                                  </body>
                                </body>
                                <body name="right_middle_proximal_link" pos="-0.0045767 0.010051 0.084993" quat="0.996681 -0.0175235 0.0746069 -0.0274369">
                                  <inertial pos="-0.00222511 5.25632e-06 0.0203008" mass="0.009" diaginertia="0.0001 0.0001 0.0001"/>
                                  <joint name="right_middle_proximal_joint" pos="0 0 0" axis="0 1 0" range="0 1.4661" actuatorfrcrange="-2 2"/>
                                  <geom name="right_middle_proximal_link_visual" type="mesh" class="visual_righthand" material="silver" mesh="right_middle_proximal_link"/>
                                  <geom name="right_middle_proximal_link_collision" type="mesh" mesh="right_middle_proximal_link"/>
                                  <body name="right_middle_distal_link" pos="0 0 0.037">
                                    <inertial pos="0.00498635 3.208e-07 0.017821" mass="0.009" diaginertia="0.0001 0.0001 0.0001"/>
                                    <joint name="right_middle_distal_joint" pos="0 0 0" axis="0 1 0" range="0 1.693" actuatorfrcrange="-2 2"/>
                                    <geom name="right_middle_distal_link_visual" type="mesh" class="visual_righthand" material="silver" mesh="right_middle_distal_link"/>
                                    <geom name="right_middle_distal_link_collision" type="mesh" mesh="right_middle_distal_link"/>
                                    <body name="right_middle_tip" pos="0.012558 0 0.040442" quat="0.971859 0 0.235565 0">
                                      <inertial pos="0 0 0" mass="0.001" diaginertia="0.0001 0.0001 0.0001"/>
                                      <geom name="right_middle_tip_visual" type="mesh" class="visual_righthand" material="silver" mesh="right_middle_tip"/>
                                      <geom name="right_middle_tip_collision" type="mesh" mesh="right_middle_tip"/>
                                      <geom name="right_middle_touch_visual" type="mesh" class="visual_righthand" material="touch" mesh="right_middle_touch_link"/>
                                      <geom name="right_middle_touch_collision" type="mesh" material="touch" mesh="right_middle_touch_link"/>
                                      <site name="right_middle_tip" pos="0 -0.05 0.015" group="4"/>
                                    </body>
                                  </body>
                                </body>
                                <body name="right_ring_proximal_link" pos="-0.0046709 -0.010037 0.083982" quat="0.996722 0.0175386 0.0740633 0.0274276">
                                  <inertial pos="-0.00234495 5.87955e-06 0.0191774" mass="0.009" diaginertia="0.0001 0.0001 0.0001"/>
                                  <joint name="right_ring_proximal_joint" pos="0 0 0" axis="0 1 0" range="0 1.4661" actuatorfrcrange="-2 2"/>
                                  <geom name="right_ring_proximal_link_visual" type="mesh" class="visual_righthand" material="silver" mesh="right_ring_proximal_link"/>
                                  <geom name="right_ring_proximal_link_collision" type="mesh" mesh="right_ring_proximal_link"/>
                                  <body name="right_ring_distal_link" pos="0 0 0.035">
                                    <inertial pos="0.00471282 -2.41852e-08 0.0172487" mass="0.009" diaginertia="0.0001 0.0001 0.0001"/>
                                    <joint name="right_ring_distal_joint" pos="0 0 0" axis="0 1 0" range="0 1.693" actuatorfrcrange="-2 2"/>
                                    <geom name="right_ring_distal_link_visual" type="mesh" class="visual_righthand" material="silver" mesh="right_ring_distal_link"/>
                                    <geom name="right_ring_distal_link_collision" type="mesh" mesh="right_ring_distal_link"/>
                                    <body name="right_ring_tip" pos="0.012266 0 0.039501" quat="0.971859 0 0.235565 0">
                                      <inertial pos="0 0 0" mass="0.001" diaginertia="0.0001 0.0001 0.0001"/>
                                      <geom name="right_ring_tip_visual" type="mesh" class="visual_righthand" material="silver" mesh="right_ring_tip"/>
                                      <geom name="right_ring_tip_collision" type="mesh" mesh="right_ring_tip"/>
                                      <geom name="right_ring_touch_visual" type="mesh" class="visual_righthand" material="touch" mesh="right_ring_touch_link"/>
                                      <geom name="right_ring_touch_collision" type="mesh" material="touch" mesh="right_ring_touch_link"/>
                                      <site name="right_ring_tip" pos="0 -0.05 0.015" group="4"/>
                                    </body>
                                  </body>
                                </body>
                                <body name="right_pinky_proximal_link" pos="-0.0023566 -0.029366 0.078694" quat="0.992245 0.052387 0.0771065 0.0822136">
                                  <inertial pos="-0.00213212 7.75039e-06 0.0160672" mass="0.009" diaginertia="0.0001 0.0001 0.0001"/>
                                  <joint name="right_pinky_proximal_joint" pos="0 0 0" axis="0 1 0" range="0 1.4661" actuatorfrcrange="-2 2"/>
                                  <geom name="right_pinky_proximal_link_visual" type="mesh" class="visual_righthand" material="silver" mesh="right_pinky_proximal_link"/>
                                  <geom name="right_pinky_proximal_link_collision" type="mesh" mesh="right_pinky_proximal_link"/>
                                  <body name="right_pinky_distal_link" pos="0 0 0.029">
                                    <inertial pos="0.00398576 -1.18733e-07 0.0141074" mass="0.009" diaginertia="0.0001 0.0001 0.0001"/>
                                    <joint name="right_pinky_distal_joint" pos="0 0 0" axis="0 1 0" range="0 1.693" actuatorfrcrange="-2 2"/>
                                    <geom name="right_pinky_distal_link_visual" type="mesh" class="visual_righthand" material="silver" mesh="right_pinky_distal_link"/>
                                    <geom name="right_pinky_distal_link_collision" type="mesh" mesh="right_pinky_distal_link"/>
                                    <body name="right_pinky_tip" pos="0.010221 0 0.032918" quat="0.971859 0 0.235565 0">
                                      <inertial pos="0 0 0" mass="0.001" diaginertia="0.0001 0.0001 0.0001"/>
                                      <geom name="right_pinky_tip_visual" type="mesh" class="visual_righthand" material="silver" mesh="right_pinky_tip"/>
                                      <geom name="right_pinky_tip_collision" type="mesh" mesh="right_pinky_tip"/>
                                      <geom name="right_pinky_touch_visual" type="mesh" class="visual_righthand" material="touch" mesh="right_pinky_touch_link"/>
                                      <geom name="right_pinky_touch_collision" type="mesh" material="touch" mesh="right_pinky_touch_link"/>
                                      <site name="right_pinky_tip" pos="0 -0.05 0.015" group="4"/>
                                    </body>
                                  </body>
                                </body>
                              </body>
                            </body>
                          </body>
                        </body>
                      </body>
                    </body>
                  </body>
                </body>
              </body>
            </body>
          </body>
        </body>
      </body>
    </body>
  </worldbody>

  <actuator>
    <motor name="left_hip_pitch" joint="left_hip_pitch_joint" ctrlrange="-88 88" />
    <motor name="left_hip_roll" joint="left_hip_roll_joint" ctrlrange="-88 88" />
    <motor name="left_hip_yaw" joint="left_hip_yaw_joint" ctrlrange="-88 88" />
    <motor name="left_knee" joint="left_knee_joint" ctrlrange="-139 139" />
    <motor name="left_ankle_pitch" joint="left_ankle_pitch_joint" ctrlrange="-50 50" />
    <motor name="left_ankle_roll" joint="left_ankle_roll_joint" ctrlrange="-50 50" />

    <motor name="right_hip_pitch" joint="right_hip_pitch_joint" ctrlrange="-88 88" />
    <motor name="right_hip_roll" joint="right_hip_roll_joint" ctrlrange="-88 88" />
    <motor name="right_hip_yaw" joint="right_hip_yaw_joint" ctrlrange="-88 88" />
    <motor name="right_knee" joint="right_knee_joint" ctrlrange="-139 139" />
    <motor name="right_ankle_pitch" joint="right_ankle_pitch_joint" ctrlrange="-50 50" />
    <motor name="right_ankle_roll" joint="right_ankle_roll_joint" ctrlrange="-50 50" />

    <motor name="waist_yaw" joint="waist_yaw_joint" ctrlrange="-88 88" />
    <motor name="waist_roll" joint="waist_roll_joint" ctrlrange="-50 50" />
    <motor name="waist_pitch" joint="waist_pitch_joint" ctrlrange="-50 50" />

    <motor name="left_shoulder_pitch" joint="left_shoulder_pitch_joint" ctrlrange="-25 25" />
    <motor name="left_shoulder_roll" joint="left_shoulder_roll_joint" ctrlrange="-25 25" />
    <motor name="left_shoulder_yaw" joint="left_shoulder_yaw_joint" ctrlrange="-25 25" />
    <motor name="left_elbow" joint="left_elbow_joint" ctrlrange="-25 25" />
    <motor name="left_wrist_roll" joint="left_wrist_roll_joint" ctrlrange="-25 25" />
    <motor name="left_wrist_pitch" joint="left_wrist_pitch_joint" ctrlrange="-5 5" />
    <motor name="left_wrist_yaw" joint="left_wrist_yaw_joint" ctrlrange="-5 5" />

    <motor name="right_shoulder_pitch" joint="right_shoulder_pitch_joint" ctrlrange="-25 25" />
    <motor name="right_shoulder_roll" joint="right_shoulder_roll_joint" ctrlrange="-25 25" />
    <motor name="right_shoulder_yaw" joint="right_shoulder_yaw_joint" ctrlrange="-25 25" />
    <motor name="right_elbow" joint="right_elbow_joint" ctrlrange="-25 25" />
    <motor name="right_wrist_roll" joint="right_wrist_roll_joint" ctrlrange="-25 25" />
    <motor name="right_wrist_pitch" joint="right_wrist_pitch_joint" ctrlrange="-5 5" />
    <motor name="right_wrist_yaw" joint="right_wrist_yaw_joint" ctrlrange="-5 5" />

    <motor name="left_thumb_metacarpal" joint="left_thumb_metacarpal_joint" ctrlrange="-0.5 0.5" />
    <motor name="left_thumb_proximal" joint="left_thumb_proximal_joint" ctrlrange="-1.1 1.1" />
    <motor name="left_index_proximal" joint="left_index_proximal_joint" ctrlrange="-2 2" />
    <motor name="left_middle_proximal" joint="left_middle_proximal_joint" ctrlrange="-2 2" />
    <motor name="left_ring_proximal" joint="left_ring_proximal_joint" ctrlrange="-2 2" />
    <motor name="left_pinky_proximal" joint="left_pinky_proximal_joint" ctrlrange="-2 2" />

    <motor name="right_thumb_metacarpal" joint="right_thumb_metacarpal_joint" ctrlrange="-0.5 0.5" />
    <motor name="right_thumb_proximal" joint="right_thumb_proximal_joint" ctrlrange="-1.1 1.1" />
    <motor name="right_index_proximal" joint="right_index_proximal_joint" ctrlrange="-2 2" />
    <motor name="right_middle_proximal" joint="right_middle_proximal_joint" ctrlrange="-2 2" />
    <motor name="right_ring_proximal" joint="right_ring_proximal_joint" ctrlrange="-2 2" />
    <motor name="right_pinky_proximal" joint="right_pinky_proximal_joint" ctrlrange="-2 2" />
  </actuator>

  <equality>
    <joint joint1="left_index_proximal_joint" joint2="left_index_distal_joint" polycoef="0 1. 0 0"/>
    <joint joint1="left_middle_proximal_joint" joint2="left_middle_distal_joint" polycoef="0 1.155 0 0"/>
    <joint joint1="left_ring_proximal_joint" joint2="left_ring_distal_joint" polycoef="0 1.155 0 0"/>
    <joint joint1="left_pinky_proximal_joint" joint2="left_pinky_distal_joint" polycoef="0 1.155 0 0"/>
    <joint joint1="left_thumb_proximal_joint" joint2="left_thumb_distal_joint" polycoef="0 1.155 0 0"/>
    <joint joint1="right_index_proximal_joint" joint2="right_index_distal_joint" polycoef="0 1. 0 0"/>
    <joint joint1="right_middle_proximal_joint" joint2="right_middle_distal_joint" polycoef="0 1.155 0 0"/>
    <joint joint1="right_ring_proximal_joint" joint2="right_ring_distal_joint" polycoef="0 1.155 0 0"/>
    <joint joint1="right_pinky_proximal_joint" joint2="right_pinky_distal_joint" polycoef="0 1.155 0 0"/>
    <joint joint1="right_thumb_proximal_joint" joint2="right_thumb_distal_joint" polycoef="0 1.155 0 0"/>
  </equality>

  <sensor>
    <jointpos name="left_hip_pitch_pos" joint="left_hip_pitch_joint" />
    <jointpos name="left_hip_roll_pos" joint="left_hip_roll_joint" />
    <jointpos name="left_hip_yaw_pos" joint="left_hip_yaw_joint" />
    <jointpos name="left_knee_pos" joint="left_knee_joint" />
    <jointpos name="left_ankle_pitch_pos" joint="left_ankle_pitch_joint" />
    <jointpos name="left_ankle_roll_pos" joint="left_ankle_roll_joint" />
    <jointpos name="right_hip_pitch_pos" joint="right_hip_pitch_joint" />
    <jointpos name="right_hip_roll_pos" joint="right_hip_roll_joint" />
    <jointpos name="right_hip_yaw_pos" joint="right_hip_yaw_joint" />
    <jointpos name="right_knee_pos" joint="right_knee_joint" />
    <jointpos name="right_ankle_pitch_pos" joint="right_ankle_pitch_joint" />
    <jointpos name="right_ankle_roll_pos" joint="right_ankle_roll_joint" />
    <jointpos name="waist_yaw_pos" joint="waist_yaw_joint" />
    <jointpos name="waist_roll_pos" joint="waist_roll_joint" />
    <jointpos name="waist_pitch_pos" joint="waist_pitch_joint" />
    <jointpos name="left_shoulder_pitch_pos" joint="left_shoulder_pitch_joint" />
    <jointpos name="left_shoulder_roll_pos" joint="left_shoulder_roll_joint" />
    <jointpos name="left_shoulder_yaw_pos" joint="left_shoulder_yaw_joint" />
    <jointpos name="left_elbow_pos" joint="left_elbow_joint" />
    <jointpos name="left_wrist_roll_pos" joint="left_wrist_roll_joint" />
    <jointpos name="left_wrist_pitch_pos" joint="left_wrist_pitch_joint" />
    <jointpos name="left_wrist_yaw_pos" joint="left_wrist_yaw_joint" />
    <jointpos name="right_shoulder_pitch_pos" joint="right_shoulder_pitch_joint" />
    <jointpos name="right_shoulder_roll_pos" joint="right_shoulder_roll_joint" />
    <jointpos name="right_shoulder_yaw_pos" joint="right_shoulder_yaw_joint" />
    <jointpos name="right_elbow_pos" joint="right_elbow_joint" />
    <jointpos name="right_wrist_roll_pos" joint="right_wrist_roll_joint" />
    <jointpos name="right_wrist_pitch_pos" joint="right_wrist_pitch_joint" />
    <jointpos name="right_wrist_yaw_pos" joint="right_wrist_yaw_joint" />
    <jointpos name="left_thumb_metacarpal_pos" joint="left_thumb_metacarpal_joint" />
    <jointpos name="left_thumb_proximal_pos" joint="left_thumb_proximal_joint" />
    <jointpos name="left_thumb_distal_pos" joint="left_thumb_distal_joint" />
    <jointpos name="left_index_proximal_pos" joint="left_index_proximal_joint" />
    <jointpos name="left_index_distal_pos" joint="left_index_distal_joint" />
    <jointpos name="left_middle_proximal_pos" joint="left_middle_proximal_joint" />
    <jointpos name="left_middle_distal_pos" joint="left_middle_distal_joint" />
    <jointpos name="left_ring_proximal_pos" joint="left_ring_proximal_joint" />
    <jointpos name="left_ring_distal_pos" joint="left_ring_distal_joint" />
    <jointpos name="left_pinky_proximal_pos" joint="left_pinky_proximal_joint" />
    <jointpos name="left_pinky_distal_pos" joint="left_pinky_distal_joint" />
    <jointpos name="right_thumb_metacarpal_pos" joint="right_thumb_metacarpal_joint" />
    <jointpos name="right_thumb_proximal_pos" joint="right_thumb_proximal_joint" />
    <jointpos name="right_thumb_distal_pos" joint="right_thumb_distal_joint" />
    <jointpos name="right_index_proximal_pos" joint="right_index_proximal_joint" />
    <jointpos name="right_index_distal_pos" joint="right_index_distal_joint" />
    <jointpos name="right_middle_proximal_pos" joint="right_middle_proximal_joint" />
    <jointpos name="right_middle_distal_pos" joint="right_middle_distal_joint" />
    <jointpos name="right_ring_proximal_pos" joint="right_ring_proximal_joint" />
    <jointpos name="right_ring_distal_pos" joint="right_ring_distal_joint" />
    <jointpos name="right_pinky_proximal_pos" joint="right_pinky_proximal_joint" />
    <jointpos name="right_pinky_distal_pos" joint="right_pinky_distal_joint" />

    <jointvel name="left_hip_pitch_vel" joint="left_hip_pitch_joint" />
    <jointvel name="left_hip_roll_vel" joint="left_hip_roll_joint" />
    <jointvel name="left_hip_yaw_vel" joint="left_hip_yaw_joint" />
    <jointvel name="left_knee_vel" joint="left_knee_joint" />
    <jointvel name="left_ankle_pitch_vel" joint="left_ankle_pitch_joint" />
    <jointvel name="left_ankle_roll_vel" joint="left_ankle_roll_joint" />
    <jointvel name="right_hip_pitch_vel" joint="right_hip_pitch_joint" />
    <jointvel name="right_hip_roll_vel" joint="right_hip_roll_joint" />
    <jointvel name="right_hip_yaw_vel" joint="right_hip_yaw_joint" />
    <jointvel name="right_knee_vel" joint="right_knee_joint" />
    <jointvel name="right_ankle_pitch_vel" joint="right_ankle_pitch_joint" />
    <jointvel name="right_ankle_roll_vel" joint="right_ankle_roll_joint" />
    <jointvel name="waist_yaw_vel" joint="waist_yaw_joint" />
    <jointvel name="waist_roll_vel" joint="waist_roll_joint" />
    <jointvel name="waist_pitch_vel" joint="waist_pitch_joint" />
    <jointvel name="left_shoulder_pitch_vel" joint="left_shoulder_pitch_joint" />
    <jointvel name="left_shoulder_roll_vel" joint="left_shoulder_roll_joint" />
    <jointvel name="left_shoulder_yaw_vel" joint="left_shoulder_yaw_joint" />
    <jointvel name="left_elbow_vel" joint="left_elbow_joint" />
    <jointvel name="left_wrist_roll_vel" joint="left_wrist_roll_joint" />
    <jointvel name="left_wrist_pitch_vel" joint="left_wrist_pitch_joint" />
    <jointvel name="left_wrist_yaw_vel" joint="left_wrist_yaw_joint" />
    <jointvel name="right_shoulder_pitch_vel" joint="right_shoulder_pitch_joint" />
    <jointvel name="right_shoulder_roll_vel" joint="right_shoulder_roll_joint" />
    <jointvel name="right_shoulder_yaw_vel" joint="right_shoulder_yaw_joint" />
    <jointvel name="right_elbow_vel" joint="right_elbow_joint" />
    <jointvel name="right_wrist_roll_vel" joint="right_wrist_roll_joint" />
    <jointvel name="right_wrist_pitch_vel" joint="right_wrist_pitch_joint" />
    <jointvel name="right_wrist_yaw_vel" joint="right_wrist_yaw_joint" />
    <jointvel name="left_thumb_metacarpal_vel" joint="left_thumb_metacarpal_joint" />
    <jointvel name="left_thumb_proximal_vel" joint="left_thumb_proximal_joint" />
    <jointvel name="left_thumb_distal_vel" joint="left_thumb_distal_joint" />
    <jointvel name="left_index_proximal_vel" joint="left_index_proximal_joint" />
    <jointvel name="left_index_distal_vel" joint="left_index_distal_joint" />
    <jointvel name="left_middle_proximal_vel" joint="left_middle_proximal_joint" />
    <jointvel name="left_middle_distal_vel" joint="left_middle_distal_joint" />
    <jointvel name="left_ring_proximal_vel" joint="left_ring_proximal_joint" />
    <jointvel name="left_ring_distal_vel" joint="left_ring_distal_joint" />
    <jointvel name="left_pinky_proximal_vel" joint="left_pinky_proximal_joint" />
    <jointvel name="left_pinky_distal_vel" joint="left_pinky_distal_joint" />
    <jointvel name="right_thumb_metacarpal_vel" joint="right_thumb_metacarpal_joint" />
    <jointvel name="right_thumb_proximal_vel" joint="right_thumb_proximal_joint" />
    <jointvel name="right_thumb_distal_vel" joint="right_thumb_distal_joint" />
    <jointvel name="right_index_proximal_vel" joint="right_index_proximal_joint" />
    <jointvel name="right_index_distal_vel" joint="right_index_distal_joint" />
    <jointvel name="right_middle_proximal_vel" joint="right_middle_proximal_joint" />
    <jointvel name="right_middle_distal_vel" joint="right_middle_distal_joint" />
    <jointvel name="right_ring_proximal_vel" joint="right_ring_proximal_joint" />
    <jointvel name="right_ring_distal_vel" joint="right_ring_distal_joint" />
    <jointvel name="right_pinky_proximal_vel" joint="right_pinky_proximal_joint" />
    <jointvel name="right_pinky_distal_vel" joint="right_pinky_distal_joint" />

    <jointactuatorfrc name="left_hip_pitch_torque" joint="left_hip_pitch_joint" />
    <jointactuatorfrc name="left_hip_roll_torque" joint="left_hip_roll_joint" />
    <jointactuatorfrc name="left_hip_yaw_torque" joint="left_hip_yaw_joint" />
    <jointactuatorfrc name="left_knee_torque" joint="left_knee_joint" />
    <jointactuatorfrc name="left_ankle_pitch_torque" joint="left_ankle_pitch_joint" />
    <jointactuatorfrc name="left_ankle_roll_torque" joint="left_ankle_roll_joint" />
    <jointactuatorfrc name="right_hip_pitch_torque" joint="right_hip_pitch_joint" />
    <jointactuatorfrc name="right_hip_roll_torque" joint="right_hip_roll_joint" />
    <jointactuatorfrc name="right_hip_yaw_torque" joint="right_hip_yaw_joint" />
    <jointactuatorfrc name="right_knee_torque" joint="right_knee_joint" />
    <jointactuatorfrc name="right_ankle_pitch_torque" joint="right_ankle_pitch_joint" />
    <jointactuatorfrc name="right_ankle_roll_torque" joint="right_ankle_roll_joint" />
    <jointactuatorfrc name="waist_yaw_torque" joint="waist_yaw_joint" />
    <jointactuatorfrc name="waist_roll_torque" joint="waist_roll_joint" />
    <jointactuatorfrc name="waist_pitch_torque" joint="waist_pitch_joint" />
    <jointactuatorfrc name="left_shoulder_pitch_torque" joint="left_shoulder_pitch_joint" />
    <jointactuatorfrc name="left_shoulder_roll_torque" joint="left_shoulder_roll_joint" />
    <jointactuatorfrc name="left_shoulder_yaw_torque" joint="left_shoulder_yaw_joint" />
    <jointactuatorfrc name="left_elbow_torque" joint="left_elbow_joint" />
    <jointactuatorfrc name="left_wrist_roll_torque" joint="left_wrist_roll_joint" />
    <jointactuatorfrc name="left_wrist_pitch_torque" joint="left_wrist_pitch_joint" />
    <jointactuatorfrc name="left_wrist_yaw_torque" joint="left_wrist_yaw_joint" />
    <jointactuatorfrc name="right_shoulder_pitch_torque" joint="right_shoulder_pitch_joint" />
    <jointactuatorfrc name="right_shoulder_roll_torque" joint="right_shoulder_roll_joint" />
    <jointactuatorfrc name="right_shoulder_yaw_torque" joint="right_shoulder_yaw_joint" />
    <jointactuatorfrc name="right_elbow_torque" joint="right_elbow_joint" />
    <jointactuatorfrc name="right_wrist_roll_torque" joint="right_wrist_roll_joint" />
    <jointactuatorfrc name="right_wrist_pitch_torque" joint="right_wrist_pitch_joint" />
    <jointactuatorfrc name="right_wrist_yaw_torque" joint="right_wrist_yaw_joint" />
    <jointactuatorfrc name="left_thumb_metacarpal_torque" joint="left_thumb_metacarpal_joint" />
    <jointactuatorfrc name="left_thumb_proximal_torque" joint="left_thumb_proximal_joint" />
    <jointactuatorfrc name="left_index_proximal_torque" joint="left_index_proximal_joint" />
    <jointactuatorfrc name="left_middle_proximal_torque" joint="left_middle_proximal_joint" />
    <jointactuatorfrc name="left_ring_proximal_torque" joint="left_ring_proximal_joint" />
    <jointactuatorfrc name="left_pinky_proximal_torque" joint="left_pinky_proximal_joint" />
    <jointactuatorfrc name="right_thumb_metacarpal_torque" joint="right_thumb_metacarpal_joint" />
    <jointactuatorfrc name="right_thumb_proximal_torque" joint="right_thumb_proximal_joint" />
    <jointactuatorfrc name="right_index_proximal_torque" joint="right_index_proximal_joint" />
    <jointactuatorfrc name="right_middle_proximal_torque" joint="right_middle_proximal_joint" />
    <jointactuatorfrc name="right_ring_proximal_torque" joint="right_ring_proximal_joint" />
    <jointactuatorfrc name="right_pinky_proximal_torque" joint="right_pinky_proximal_joint" />

    <framequat name="imu_quat" objtype="site" objname="imu" />
    <gyro name="imu_gyro" site="imu" />
    <accelerometer name="imu_acc" site="imu" />

    <framepos name="frame_pos" objtype="site" objname="imu" />
    <framelinvel name="frame_vel" objtype="site" objname="imu" />

    <framequat name="secondary_imu_quat" objtype="site" objname="secondary_imu" />
    <gyro name="secondary_imu_gyro" site="secondary_imu" noise="5e-4" cutoff="34.9"/>
    <accelerometer name="secondary_imu_acc" site="secondary_imu" noise="1e-2" cutoff="157"/>
  </sensor>

</mujoco>